[2024-02-17T23:21:40.797+0000] {taskinstance.py:1159} INFO - Dependencies all met for dep_context=non-requeueable deps ti=<TaskInstance: api_to_mysql.load_data_to_mysql manual__2024-02-17T23:21:34.807775+00:00 [queued]>
[2024-02-17T23:21:40.808+0000] {taskinstance.py:1159} INFO - Dependencies all met for dep_context=requeueable deps ti=<TaskInstance: api_to_mysql.load_data_to_mysql manual__2024-02-17T23:21:34.807775+00:00 [queued]>
[2024-02-17T23:21:40.808+0000] {taskinstance.py:1361} INFO - Starting attempt 1 of 1
[2024-02-17T23:21:40.829+0000] {taskinstance.py:1382} INFO - Executing <Task(PythonOperator): load_data_to_mysql> on 2024-02-17 23:21:34.807775+00:00
[2024-02-17T23:21:40.839+0000] {standard_task_runner.py:57} INFO - Started process 22316 to run task
[2024-02-17T23:21:40.843+0000] {standard_task_runner.py:84} INFO - Running: ['airflow', 'tasks', 'run', 'api_to_mysql', 'load_data_to_mysql', 'manual__2024-02-17T23:21:34.807775+00:00', '--job-id', '17', '--raw', '--subdir', 'DAGS_FOLDER/teste_api_to_mysql.py', '--cfg-path', '/tmp/tmpzgi5yp8j']
[2024-02-17T23:21:40.844+0000] {standard_task_runner.py:85} INFO - Job 17: Subtask load_data_to_mysql
[2024-02-17T23:21:40.996+0000] {task_command.py:416} INFO - Running <TaskInstance: api_to_mysql.load_data_to_mysql manual__2024-02-17T23:21:34.807775+00:00 [running]> on host airflow-worker
[2024-02-17T23:21:41.251+0000] {taskinstance.py:1662} INFO - Exporting env vars: AIRFLOW_CTX_DAG_OWNER='airflow' AIRFLOW_CTX_DAG_ID='api_to_mysql' AIRFLOW_CTX_TASK_ID='load_data_to_mysql' AIRFLOW_CTX_EXECUTION_DATE='2024-02-17T23:21:34.807775+00:00' AIRFLOW_CTX_TRY_NUMBER='1' AIRFLOW_CTX_DAG_RUN_ID='manual__2024-02-17T23:21:34.807775+00:00'
[2024-02-17T23:21:41.253+0000] {taskinstance.py:1937} ERROR - Task failed with exception
Traceback (most recent call last):
  File "/home/airflow/.local/lib/python3.8/site-packages/airflow/operators/python.py", line 192, in execute
    return_value = self.execute_callable()
  File "/home/airflow/.local/lib/python3.8/site-packages/airflow/operators/python.py", line 209, in execute_callable
    return self.python_callable(*self.op_args, **self.op_kwargs)
  File "/opt/airflow/dags/teste_api_to_mysql.py", line 26, in load_data_to_mysql
    data = kwargs['ti'].xcom_pull(task_ids='extract_data')
NameError: name 'kwargs' is not defined
[2024-02-17T23:21:41.294+0000] {taskinstance.py:1400} INFO - Marking task as FAILED. dag_id=api_to_mysql, task_id=load_data_to_mysql, execution_date=20240217T232134, start_date=20240217T232140, end_date=20240217T232141
[2024-02-17T23:21:41.334+0000] {standard_task_runner.py:104} ERROR - Failed to execute job 17 for task load_data_to_mysql (name 'kwargs' is not defined; 22316)
[2024-02-17T23:21:41.347+0000] {local_task_job_runner.py:228} INFO - Task exited with return code 1
[2024-02-17T23:21:41.400+0000] {taskinstance.py:2778} INFO - 0 downstream tasks scheduled from follow-on schedule check
