[2024-02-18T01:21:48.719+0000] {taskinstance.py:1159} INFO - Dependencies all met for dep_context=non-requeueable deps ti=<TaskInstance: api_to_local.extract_and_save manual__2024-02-18T01:21:46.472573+00:00 [queued]>
[2024-02-18T01:21:48.728+0000] {taskinstance.py:1159} INFO - Dependencies all met for dep_context=requeueable deps ti=<TaskInstance: api_to_local.extract_and_save manual__2024-02-18T01:21:46.472573+00:00 [queued]>
[2024-02-18T01:21:48.728+0000] {taskinstance.py:1361} INFO - Starting attempt 1 of 1
[2024-02-18T01:21:48.747+0000] {taskinstance.py:1382} INFO - Executing <Task(PythonOperator): extract_and_save> on 2024-02-18 01:21:46.472573+00:00
[2024-02-18T01:21:48.753+0000] {standard_task_runner.py:57} INFO - Started process 24321 to run task
[2024-02-18T01:21:48.756+0000] {standard_task_runner.py:84} INFO - Running: ['airflow', 'tasks', 'run', 'api_to_local', 'extract_and_save', 'manual__2024-02-18T01:21:46.472573+00:00', '--job-id', '66', '--raw', '--subdir', 'DAGS_FOLDER/api_to_local.py', '--cfg-path', '/tmp/tmp83czkvvo']
[2024-02-18T01:21:48.758+0000] {standard_task_runner.py:85} INFO - Job 66: Subtask extract_and_save
[2024-02-18T01:21:48.912+0000] {task_command.py:416} INFO - Running <TaskInstance: api_to_local.extract_and_save manual__2024-02-18T01:21:46.472573+00:00 [running]> on host airflow-worker
[2024-02-18T01:21:49.188+0000] {taskinstance.py:1662} INFO - Exporting env vars: AIRFLOW_CTX_DAG_OWNER='airflow' AIRFLOW_CTX_DAG_ID='api_to_local' AIRFLOW_CTX_TASK_ID='extract_and_save' AIRFLOW_CTX_EXECUTION_DATE='2024-02-18T01:21:46.472573+00:00' AIRFLOW_CTX_TRY_NUMBER='1' AIRFLOW_CTX_DAG_RUN_ID='manual__2024-02-18T01:21:46.472573+00:00'
[2024-02-18T01:21:49.840+0000] {taskinstance.py:1937} ERROR - Task failed with exception
Traceback (most recent call last):
  File "/home/airflow/.local/lib/python3.8/site-packages/airflow/operators/python.py", line 192, in execute
    return_value = self.execute_callable()
  File "/home/airflow/.local/lib/python3.8/site-packages/airflow/operators/python.py", line 209, in execute_callable
    return self.python_callable(*self.op_args, **self.op_kwargs)
  File "/opt/airflow/dags/api_to_local.py", line 11, in extract_from_api_and_save_local
    with open('./caminho/para/o/arquivo/dados.json', 'w') as f:
FileNotFoundError: [Errno 2] No such file or directory: './caminho/para/o/arquivo/dados.json'
[2024-02-18T01:21:49.936+0000] {taskinstance.py:1400} INFO - Marking task as FAILED. dag_id=api_to_local, task_id=extract_and_save, execution_date=20240218T012146, start_date=20240218T012148, end_date=20240218T012149
[2024-02-18T01:21:49.982+0000] {standard_task_runner.py:104} ERROR - Failed to execute job 66 for task extract_and_save ([Errno 2] No such file or directory: './caminho/para/o/arquivo/dados.json'; 24321)
[2024-02-18T01:21:50.008+0000] {local_task_job_runner.py:228} INFO - Task exited with return code 1
[2024-02-18T01:21:50.069+0000] {taskinstance.py:2778} INFO - 0 downstream tasks scheduled from follow-on schedule check
