[2024-02-17T18:01:44.155+0000] {taskinstance.py:1159} INFO - Dependencies all met for dep_context=non-requeueable deps ti=<TaskInstance: api_to_mysql.transform_data manual__2024-02-17T18:01:38.307093+00:00 [queued]>
[2024-02-17T18:01:44.163+0000] {taskinstance.py:1159} INFO - Dependencies all met for dep_context=requeueable deps ti=<TaskInstance: api_to_mysql.transform_data manual__2024-02-17T18:01:38.307093+00:00 [queued]>
[2024-02-17T18:01:44.163+0000] {taskinstance.py:1361} INFO - Starting attempt 1 of 1
[2024-02-17T18:01:44.180+0000] {taskinstance.py:1382} INFO - Executing <Task(PythonOperator): transform_data> on 2024-02-17 18:01:38.307093+00:00
[2024-02-17T18:01:44.185+0000] {standard_task_runner.py:57} INFO - Started process 17350 to run task
[2024-02-17T18:01:44.188+0000] {standard_task_runner.py:84} INFO - Running: ['airflow', 'tasks', 'run', 'api_to_mysql', 'transform_data', 'manual__2024-02-17T18:01:38.307093+00:00', '--job-id', '4', '--raw', '--subdir', 'DAGS_FOLDER/teste_api_to_mysql.py', '--cfg-path', '/tmp/tmp7bhb35ay']
[2024-02-17T18:01:44.189+0000] {standard_task_runner.py:85} INFO - Job 4: Subtask transform_data
[2024-02-17T18:01:44.329+0000] {task_command.py:416} INFO - Running <TaskInstance: api_to_mysql.transform_data manual__2024-02-17T18:01:38.307093+00:00 [running]> on host airflow-worker
[2024-02-17T18:01:44.577+0000] {taskinstance.py:1662} INFO - Exporting env vars: AIRFLOW_CTX_DAG_OWNER='airflow' AIRFLOW_CTX_DAG_ID='api_to_mysql' AIRFLOW_CTX_TASK_ID='transform_data' AIRFLOW_CTX_EXECUTION_DATE='2024-02-17T18:01:38.307093+00:00' AIRFLOW_CTX_TRY_NUMBER='1' AIRFLOW_CTX_DAG_RUN_ID='manual__2024-02-17T18:01:38.307093+00:00'
[2024-02-17T18:01:44.579+0000] {taskinstance.py:1937} ERROR - Task failed with exception
Traceback (most recent call last):
  File "/home/airflow/.local/lib/python3.8/site-packages/airflow/operators/python.py", line 192, in execute
    return_value = self.execute_callable()
  File "/home/airflow/.local/lib/python3.8/site-packages/airflow/operators/python.py", line 209, in execute_callable
    return self.python_callable(*self.op_args, **self.op_kwargs)
TypeError: transform_data() missing 1 required positional argument: 'data'
[2024-02-17T18:01:44.618+0000] {taskinstance.py:1400} INFO - Marking task as FAILED. dag_id=api_to_mysql, task_id=transform_data, execution_date=20240217T180138, start_date=20240217T180144, end_date=20240217T180144
[2024-02-17T18:01:44.649+0000] {standard_task_runner.py:104} ERROR - Failed to execute job 4 for task transform_data (transform_data() missing 1 required positional argument: 'data'; 17350)
[2024-02-17T18:01:44.693+0000] {local_task_job_runner.py:228} INFO - Task exited with return code 1
[2024-02-17T18:01:44.753+0000] {taskinstance.py:2778} INFO - 0 downstream tasks scheduled from follow-on schedule check
