[2024-02-17T23:28:39.092+0000] {taskinstance.py:1159} INFO - Dependencies all met for dep_context=non-requeueable deps ti=<TaskInstance: api_to_mysql_with_xcom.save_to_mysql manual__2024-02-17T23:28:33.599497+00:00 [queued]>
[2024-02-17T23:28:39.101+0000] {taskinstance.py:1159} INFO - Dependencies all met for dep_context=requeueable deps ti=<TaskInstance: api_to_mysql_with_xcom.save_to_mysql manual__2024-02-17T23:28:33.599497+00:00 [queued]>
[2024-02-17T23:28:39.101+0000] {taskinstance.py:1361} INFO - Starting attempt 1 of 1
[2024-02-17T23:28:39.118+0000] {taskinstance.py:1382} INFO - Executing <Task(PythonOperator): save_to_mysql> on 2024-02-17 23:28:33.599497+00:00
[2024-02-17T23:28:39.124+0000] {standard_task_runner.py:57} INFO - Started process 22440 to run task
[2024-02-17T23:28:39.126+0000] {standard_task_runner.py:84} INFO - Running: ['airflow', 'tasks', 'run', 'api_to_mysql_with_xcom', 'save_to_mysql', 'manual__2024-02-17T23:28:33.599497+00:00', '--job-id', '21', '--raw', '--subdir', 'DAGS_FOLDER/teste_api2.py', '--cfg-path', '/tmp/tmpqh6huddm']
[2024-02-17T23:28:39.128+0000] {standard_task_runner.py:85} INFO - Job 21: Subtask save_to_mysql
[2024-02-17T23:28:39.277+0000] {task_command.py:416} INFO - Running <TaskInstance: api_to_mysql_with_xcom.save_to_mysql manual__2024-02-17T23:28:33.599497+00:00 [running]> on host airflow-worker
[2024-02-17T23:28:39.527+0000] {taskinstance.py:1662} INFO - Exporting env vars: AIRFLOW_CTX_DAG_OWNER='airflow' AIRFLOW_CTX_DAG_ID='api_to_mysql_with_xcom' AIRFLOW_CTX_TASK_ID='save_to_mysql' AIRFLOW_CTX_EXECUTION_DATE='2024-02-17T23:28:33.599497+00:00' AIRFLOW_CTX_TRY_NUMBER='1' AIRFLOW_CTX_DAG_RUN_ID='manual__2024-02-17T23:28:33.599497+00:00'
[2024-02-17T23:28:39.579+0000] {taskinstance.py:1937} ERROR - Task failed with exception
Traceback (most recent call last):
  File "/home/airflow/.local/lib/python3.8/site-packages/airflow/operators/python.py", line 192, in execute
    return_value = self.execute_callable()
  File "/home/airflow/.local/lib/python3.8/site-packages/airflow/operators/python.py", line 209, in execute_callable
    return self.python_callable(*self.op_args, **self.op_kwargs)
  File "/opt/airflow/dags/teste_api2.py", line 24, in save_to_mysql
    engine = create_engine(f'mysql://{MYSQL_CONN_ID}')
NameError: name 'create_engine' is not defined
[2024-02-17T23:28:39.617+0000] {taskinstance.py:1400} INFO - Marking task as FAILED. dag_id=api_to_mysql_with_xcom, task_id=save_to_mysql, execution_date=20240217T232833, start_date=20240217T232839, end_date=20240217T232839
[2024-02-17T23:28:39.659+0000] {standard_task_runner.py:104} ERROR - Failed to execute job 21 for task save_to_mysql (name 'create_engine' is not defined; 22440)
[2024-02-17T23:28:39.669+0000] {local_task_job_runner.py:228} INFO - Task exited with return code 1
[2024-02-17T23:28:39.725+0000] {taskinstance.py:2778} INFO - 0 downstream tasks scheduled from follow-on schedule check
