[2024-02-18T00:30:40.238+0000] {taskinstance.py:1159} INFO - Dependencies all met for dep_context=non-requeueable deps ti=<TaskInstance: api_teste.save_to_mysql manual__2024-02-18T00:30:34.698074+00:00 [queued]>
[2024-02-18T00:30:40.249+0000] {taskinstance.py:1159} INFO - Dependencies all met for dep_context=requeueable deps ti=<TaskInstance: api_teste.save_to_mysql manual__2024-02-18T00:30:34.698074+00:00 [queued]>
[2024-02-18T00:30:40.250+0000] {taskinstance.py:1361} INFO - Starting attempt 1 of 1
[2024-02-18T00:30:40.353+0000] {taskinstance.py:1382} INFO - Executing <Task(PythonOperator): save_to_mysql> on 2024-02-18 00:30:34.698074+00:00
[2024-02-18T00:30:40.360+0000] {standard_task_runner.py:57} INFO - Started process 23492 to run task
[2024-02-18T00:30:40.364+0000] {standard_task_runner.py:84} INFO - Running: ['airflow', 'tasks', 'run', 'api_teste', 'save_to_mysql', 'manual__2024-02-18T00:30:34.698074+00:00', '--job-id', '51', '--raw', '--subdir', 'DAGS_FOLDER/teste_api_to_mysql.py', '--cfg-path', '/tmp/tmp9ziz89kw']
[2024-02-18T00:30:40.365+0000] {standard_task_runner.py:85} INFO - Job 51: Subtask save_to_mysql
[2024-02-18T00:30:40.558+0000] {task_command.py:416} INFO - Running <TaskInstance: api_teste.save_to_mysql manual__2024-02-18T00:30:34.698074+00:00 [running]> on host airflow-worker
[2024-02-18T00:30:40.861+0000] {taskinstance.py:1662} INFO - Exporting env vars: AIRFLOW_CTX_DAG_OWNER='airflow' AIRFLOW_CTX_DAG_ID='api_teste' AIRFLOW_CTX_TASK_ID='save_to_mysql' AIRFLOW_CTX_EXECUTION_DATE='2024-02-18T00:30:34.698074+00:00' AIRFLOW_CTX_TRY_NUMBER='1' AIRFLOW_CTX_DAG_RUN_ID='manual__2024-02-18T00:30:34.698074+00:00'
[2024-02-18T00:30:40.922+0000] {taskinstance.py:1937} ERROR - Task failed with exception
Traceback (most recent call last):
  File "/home/airflow/.local/lib/python3.8/site-packages/airflow/operators/python.py", line 192, in execute
    return_value = self.execute_callable()
  File "/home/airflow/.local/lib/python3.8/site-packages/airflow/operators/python.py", line 209, in execute_callable
    return self.python_callable(*self.op_args, **self.op_kwargs)
  File "/opt/airflow/dags/teste_api_to_mysql.py", line 30, in save_to_mysql
    engine = connection = create_engine(conn.get_extra())
  File "<string>", line 2, in create_engine
  File "/home/airflow/.local/lib/python3.8/site-packages/sqlalchemy/util/deprecations.py", line 375, in warned
    return fn(*args, **kwargs)
  File "/home/airflow/.local/lib/python3.8/site-packages/sqlalchemy/engine/create.py", line 514, in create_engine
    u = _url.make_url(url)
  File "/home/airflow/.local/lib/python3.8/site-packages/sqlalchemy/engine/url.py", line 738, in make_url
    return _parse_url(name_or_url)
  File "/home/airflow/.local/lib/python3.8/site-packages/sqlalchemy/engine/url.py", line 799, in _parse_url
    raise exc.ArgumentError(
sqlalchemy.exc.ArgumentError: Could not parse SQLAlchemy URL from string ''
[2024-02-18T00:30:40.974+0000] {taskinstance.py:1400} INFO - Marking task as FAILED. dag_id=api_teste, task_id=save_to_mysql, execution_date=20240218T003034, start_date=20240218T003040, end_date=20240218T003040
[2024-02-18T00:30:41.006+0000] {standard_task_runner.py:104} ERROR - Failed to execute job 51 for task save_to_mysql (Could not parse SQLAlchemy URL from string ''; 23492)
[2024-02-18T00:30:41.024+0000] {local_task_job_runner.py:228} INFO - Task exited with return code 1
[2024-02-18T00:30:41.084+0000] {taskinstance.py:2778} INFO - 0 downstream tasks scheduled from follow-on schedule check
