[2024-02-18T00:29:30.568+0000] {taskinstance.py:1159} INFO - Dependencies all met for dep_context=non-requeueable deps ti=<TaskInstance: api_teste.save_to_mysql manual__2024-02-18T00:29:24.873479+00:00 [queued]>
[2024-02-18T00:29:30.581+0000] {taskinstance.py:1159} INFO - Dependencies all met for dep_context=requeueable deps ti=<TaskInstance: api_teste.save_to_mysql manual__2024-02-18T00:29:24.873479+00:00 [queued]>
[2024-02-18T00:29:30.581+0000] {taskinstance.py:1361} INFO - Starting attempt 1 of 1
[2024-02-18T00:29:30.603+0000] {taskinstance.py:1382} INFO - Executing <Task(PythonOperator): save_to_mysql> on 2024-02-18 00:29:24.873479+00:00
[2024-02-18T00:29:30.616+0000] {standard_task_runner.py:57} INFO - Started process 23470 to run task
[2024-02-18T00:29:30.619+0000] {standard_task_runner.py:84} INFO - Running: ['airflow', 'tasks', 'run', 'api_teste', 'save_to_mysql', 'manual__2024-02-18T00:29:24.873479+00:00', '--job-id', '49', '--raw', '--subdir', 'DAGS_FOLDER/teste_api_to_mysql.py', '--cfg-path', '/tmp/tmpt4drxa47']
[2024-02-18T00:29:30.620+0000] {standard_task_runner.py:85} INFO - Job 49: Subtask save_to_mysql
[2024-02-18T00:29:30.783+0000] {task_command.py:416} INFO - Running <TaskInstance: api_teste.save_to_mysql manual__2024-02-18T00:29:24.873479+00:00 [running]> on host airflow-worker
[2024-02-18T00:29:31.041+0000] {taskinstance.py:1662} INFO - Exporting env vars: AIRFLOW_CTX_DAG_OWNER='airflow' AIRFLOW_CTX_DAG_ID='api_teste' AIRFLOW_CTX_TASK_ID='save_to_mysql' AIRFLOW_CTX_EXECUTION_DATE='2024-02-18T00:29:24.873479+00:00' AIRFLOW_CTX_TRY_NUMBER='1' AIRFLOW_CTX_DAG_RUN_ID='manual__2024-02-18T00:29:24.873479+00:00'
[2024-02-18T00:29:31.095+0000] {taskinstance.py:1937} ERROR - Task failed with exception
Traceback (most recent call last):
  File "/home/airflow/.local/lib/python3.8/site-packages/airflow/operators/python.py", line 192, in execute
    return_value = self.execute_callable()
  File "/home/airflow/.local/lib/python3.8/site-packages/airflow/operators/python.py", line 209, in execute_callable
    return self.python_callable(*self.op_args, **self.op_kwargs)
  File "/opt/airflow/dags/teste_api_to_mysql.py", line 31, in save_to_mysql
    .format(username=username, password=password,
NameError: name 'username' is not defined
[2024-02-18T00:29:31.142+0000] {taskinstance.py:1400} INFO - Marking task as FAILED. dag_id=api_teste, task_id=save_to_mysql, execution_date=20240218T002924, start_date=20240218T002930, end_date=20240218T002931
[2024-02-18T00:29:31.173+0000] {standard_task_runner.py:104} ERROR - Failed to execute job 49 for task save_to_mysql (name 'username' is not defined; 23470)
[2024-02-18T00:29:31.207+0000] {local_task_job_runner.py:228} INFO - Task exited with return code 1
[2024-02-18T00:29:31.265+0000] {taskinstance.py:2778} INFO - 0 downstream tasks scheduled from follow-on schedule check
