[2024-02-18T00:22:14.987+0000] {taskinstance.py:1159} INFO - Dependencies all met for dep_context=non-requeueable deps ti=<TaskInstance: api_teste.save_to_mysql manual__2024-02-18T00:22:09.087750+00:00 [queued]>
[2024-02-18T00:22:14.996+0000] {taskinstance.py:1159} INFO - Dependencies all met for dep_context=requeueable deps ti=<TaskInstance: api_teste.save_to_mysql manual__2024-02-18T00:22:09.087750+00:00 [queued]>
[2024-02-18T00:22:14.996+0000] {taskinstance.py:1361} INFO - Starting attempt 1 of 1
[2024-02-18T00:22:15.014+0000] {taskinstance.py:1382} INFO - Executing <Task(PythonOperator): save_to_mysql> on 2024-02-18 00:22:09.087750+00:00
[2024-02-18T00:22:15.019+0000] {standard_task_runner.py:57} INFO - Started process 23352 to run task
[2024-02-18T00:22:15.022+0000] {standard_task_runner.py:84} INFO - Running: ['airflow', 'tasks', 'run', 'api_teste', 'save_to_mysql', 'manual__2024-02-18T00:22:09.087750+00:00', '--job-id', '47', '--raw', '--subdir', 'DAGS_FOLDER/teste_api_to_mysql.py', '--cfg-path', '/tmp/tmp0uy4aflo']
[2024-02-18T00:22:15.022+0000] {standard_task_runner.py:85} INFO - Job 47: Subtask save_to_mysql
[2024-02-18T00:22:15.187+0000] {task_command.py:416} INFO - Running <TaskInstance: api_teste.save_to_mysql manual__2024-02-18T00:22:09.087750+00:00 [running]> on host airflow-worker
[2024-02-18T00:22:15.454+0000] {taskinstance.py:1662} INFO - Exporting env vars: AIRFLOW_CTX_DAG_OWNER='airflow' AIRFLOW_CTX_DAG_ID='api_teste' AIRFLOW_CTX_TASK_ID='save_to_mysql' AIRFLOW_CTX_EXECUTION_DATE='2024-02-18T00:22:09.087750+00:00' AIRFLOW_CTX_TRY_NUMBER='1' AIRFLOW_CTX_DAG_RUN_ID='manual__2024-02-18T00:22:09.087750+00:00'
[2024-02-18T00:22:15.515+0000] {taskinstance.py:1937} ERROR - Task failed with exception
Traceback (most recent call last):
  File "/home/airflow/.local/lib/python3.8/site-packages/airflow/operators/python.py", line 192, in execute
    return_value = self.execute_callable()
  File "/home/airflow/.local/lib/python3.8/site-packages/airflow/operators/python.py", line 209, in execute_callable
    return self.python_callable(*self.op_args, **self.op_kwargs)
  File "/opt/airflow/dags/teste_api_to_mysql.py", line 26, in save_to_mysql
    .format(username=username, password=password,
NameError: name 'username' is not defined
[2024-02-18T00:22:15.557+0000] {taskinstance.py:1400} INFO - Marking task as FAILED. dag_id=api_teste, task_id=save_to_mysql, execution_date=20240218T002209, start_date=20240218T002214, end_date=20240218T002215
[2024-02-18T00:22:15.589+0000] {standard_task_runner.py:104} ERROR - Failed to execute job 47 for task save_to_mysql (name 'username' is not defined; 23352)
[2024-02-18T00:22:15.612+0000] {local_task_job_runner.py:228} INFO - Task exited with return code 1
[2024-02-18T00:22:15.671+0000] {taskinstance.py:2778} INFO - 0 downstream tasks scheduled from follow-on schedule check
