[2024-02-18T01:03:36.087+0000] {taskinstance.py:1159} INFO - Dependencies all met for dep_context=non-requeueable deps ti=<TaskInstance: api_teste.save_to_mysql manual__2024-02-18T01:03:30.079522+00:00 [queued]>
[2024-02-18T01:03:36.098+0000] {taskinstance.py:1159} INFO - Dependencies all met for dep_context=requeueable deps ti=<TaskInstance: api_teste.save_to_mysql manual__2024-02-18T01:03:30.079522+00:00 [queued]>
[2024-02-18T01:03:36.098+0000] {taskinstance.py:1361} INFO - Starting attempt 1 of 1
[2024-02-18T01:03:36.115+0000] {taskinstance.py:1382} INFO - Executing <Task(PythonOperator): save_to_mysql> on 2024-02-18 01:03:30.079522+00:00
[2024-02-18T01:03:36.122+0000] {standard_task_runner.py:57} INFO - Started process 24022 to run task
[2024-02-18T01:03:36.124+0000] {standard_task_runner.py:84} INFO - Running: ['airflow', 'tasks', 'run', 'api_teste', 'save_to_mysql', 'manual__2024-02-18T01:03:30.079522+00:00', '--job-id', '60', '--raw', '--subdir', 'DAGS_FOLDER/teste_api_to_mysql.py', '--cfg-path', '/tmp/tmpiham95kn']
[2024-02-18T01:03:36.125+0000] {standard_task_runner.py:85} INFO - Job 60: Subtask save_to_mysql
[2024-02-18T01:03:36.286+0000] {task_command.py:416} INFO - Running <TaskInstance: api_teste.save_to_mysql manual__2024-02-18T01:03:30.079522+00:00 [running]> on host airflow-worker
[2024-02-18T01:03:36.803+0000] {taskinstance.py:1662} INFO - Exporting env vars: AIRFLOW_CTX_DAG_OWNER='airflow' AIRFLOW_CTX_DAG_ID='api_teste' AIRFLOW_CTX_TASK_ID='save_to_mysql' AIRFLOW_CTX_EXECUTION_DATE='2024-02-18T01:03:30.079522+00:00' AIRFLOW_CTX_TRY_NUMBER='1' AIRFLOW_CTX_DAG_RUN_ID='manual__2024-02-18T01:03:30.079522+00:00'
[2024-02-18T01:03:36.867+0000] {taskinstance.py:1937} ERROR - Task failed with exception
Traceback (most recent call last):
  File "/home/airflow/.local/lib/python3.8/site-packages/airflow/operators/python.py", line 192, in execute
    return_value = self.execute_callable()
  File "/home/airflow/.local/lib/python3.8/site-packages/airflow/operators/python.py", line 209, in execute_callable
    return self.python_callable(*self.op_args, **self.op_kwargs)
  File "/opt/airflow/dags/teste_api_to_mysql.py", line 31, in save_to_mysql
    engine = connection = create_engine(conn.get_extra())
NameError: name 'conn' is not defined
[2024-02-18T01:03:36.909+0000] {taskinstance.py:1400} INFO - Marking task as FAILED. dag_id=api_teste, task_id=save_to_mysql, execution_date=20240218T010330, start_date=20240218T010336, end_date=20240218T010336
[2024-02-18T01:03:36.944+0000] {standard_task_runner.py:104} ERROR - Failed to execute job 60 for task save_to_mysql (name 'conn' is not defined; 24022)
[2024-02-18T01:03:36.953+0000] {local_task_job_runner.py:228} INFO - Task exited with return code 1
[2024-02-18T01:03:37.009+0000] {taskinstance.py:2778} INFO - 0 downstream tasks scheduled from follow-on schedule check
