[2024-02-17T18:05:59.679+0000] {taskinstance.py:1159} INFO - Dependencies all met for dep_context=non-requeueable deps ti=<TaskInstance: api_to_mysql.load_data_to_mysql manual__2024-02-17T18:05:54.955489+00:00 [queued]>
[2024-02-17T18:05:59.687+0000] {taskinstance.py:1159} INFO - Dependencies all met for dep_context=requeueable deps ti=<TaskInstance: api_to_mysql.load_data_to_mysql manual__2024-02-17T18:05:54.955489+00:00 [queued]>
[2024-02-17T18:05:59.688+0000] {taskinstance.py:1361} INFO - Starting attempt 1 of 1
[2024-02-17T18:05:59.711+0000] {taskinstance.py:1382} INFO - Executing <Task(PythonOperator): load_data_to_mysql> on 2024-02-17 18:05:54.955489+00:00
[2024-02-17T18:05:59.717+0000] {standard_task_runner.py:57} INFO - Started process 17429 to run task
[2024-02-17T18:05:59.722+0000] {standard_task_runner.py:84} INFO - Running: ['airflow', 'tasks', 'run', 'api_to_mysql', 'load_data_to_mysql', 'manual__2024-02-17T18:05:54.955489+00:00', '--job-id', '9', '--raw', '--subdir', 'DAGS_FOLDER/teste_api_to_mysql.py', '--cfg-path', '/tmp/tmp44hk6mgw']
[2024-02-17T18:05:59.723+0000] {standard_task_runner.py:85} INFO - Job 9: Subtask load_data_to_mysql
[2024-02-17T18:06:00.051+0000] {task_command.py:416} INFO - Running <TaskInstance: api_to_mysql.load_data_to_mysql manual__2024-02-17T18:05:54.955489+00:00 [running]> on host airflow-worker
[2024-02-17T18:06:00.402+0000] {taskinstance.py:1662} INFO - Exporting env vars: AIRFLOW_CTX_DAG_OWNER='airflow' AIRFLOW_CTX_DAG_ID='api_to_mysql' AIRFLOW_CTX_TASK_ID='load_data_to_mysql' AIRFLOW_CTX_EXECUTION_DATE='2024-02-17T18:05:54.955489+00:00' AIRFLOW_CTX_TRY_NUMBER='1' AIRFLOW_CTX_DAG_RUN_ID='manual__2024-02-17T18:05:54.955489+00:00'
[2024-02-17T18:06:00.406+0000] {taskinstance.py:1937} ERROR - Task failed with exception
Traceback (most recent call last):
  File "/home/airflow/.local/lib/python3.8/site-packages/airflow/operators/python.py", line 192, in execute
    return_value = self.execute_callable()
  File "/home/airflow/.local/lib/python3.8/site-packages/airflow/operators/python.py", line 209, in execute_callable
    return self.python_callable(*self.op_args, **self.op_kwargs)
TypeError: load_data_to_mysql() missing 1 required positional argument: 'data'
[2024-02-17T18:06:00.446+0000] {taskinstance.py:1400} INFO - Marking task as FAILED. dag_id=api_to_mysql, task_id=load_data_to_mysql, execution_date=20240217T180554, start_date=20240217T180559, end_date=20240217T180600
[2024-02-17T18:06:00.476+0000] {standard_task_runner.py:104} ERROR - Failed to execute job 9 for task load_data_to_mysql (load_data_to_mysql() missing 1 required positional argument: 'data'; 17429)
[2024-02-17T18:06:00.503+0000] {local_task_job_runner.py:228} INFO - Task exited with return code 1
[2024-02-17T18:06:00.563+0000] {taskinstance.py:2778} INFO - 0 downstream tasks scheduled from follow-on schedule check
