[2024-02-17T23:52:30.339+0000] {taskinstance.py:1159} INFO - Dependencies all met for dep_context=non-requeueable deps ti=<TaskInstance: api_to_mysql_with_xcom.save_to_mysql manual__2024-02-17T23:52:26.067225+00:00 [queued]>
[2024-02-17T23:52:30.349+0000] {taskinstance.py:1159} INFO - Dependencies all met for dep_context=requeueable deps ti=<TaskInstance: api_to_mysql_with_xcom.save_to_mysql manual__2024-02-17T23:52:26.067225+00:00 [queued]>
[2024-02-17T23:52:30.349+0000] {taskinstance.py:1361} INFO - Starting attempt 1 of 1
[2024-02-17T23:52:30.365+0000] {taskinstance.py:1382} INFO - Executing <Task(PythonOperator): save_to_mysql> on 2024-02-17 23:52:26.067225+00:00
[2024-02-17T23:52:30.373+0000] {standard_task_runner.py:57} INFO - Started process 22828 to run task
[2024-02-17T23:52:30.376+0000] {standard_task_runner.py:84} INFO - Running: ['airflow', 'tasks', 'run', 'api_to_mysql_with_xcom', 'save_to_mysql', 'manual__2024-02-17T23:52:26.067225+00:00', '--job-id', '27', '--raw', '--subdir', 'DAGS_FOLDER/teste_api2.py', '--cfg-path', '/tmp/tmpzjmdplfu']
[2024-02-17T23:52:30.376+0000] {standard_task_runner.py:85} INFO - Job 27: Subtask save_to_mysql
[2024-02-17T23:52:30.539+0000] {task_command.py:416} INFO - Running <TaskInstance: api_to_mysql_with_xcom.save_to_mysql manual__2024-02-17T23:52:26.067225+00:00 [running]> on host airflow-worker
[2024-02-17T23:52:30.794+0000] {taskinstance.py:1662} INFO - Exporting env vars: AIRFLOW_CTX_DAG_OWNER='airflow' AIRFLOW_CTX_DAG_ID='api_to_mysql_with_xcom' AIRFLOW_CTX_TASK_ID='save_to_mysql' AIRFLOW_CTX_EXECUTION_DATE='2024-02-17T23:52:26.067225+00:00' AIRFLOW_CTX_TRY_NUMBER='1' AIRFLOW_CTX_DAG_RUN_ID='manual__2024-02-17T23:52:26.067225+00:00'
[2024-02-17T23:52:30.852+0000] {taskinstance.py:1937} ERROR - Task failed with exception
Traceback (most recent call last):
  File "/home/airflow/.local/lib/python3.8/site-packages/airflow/operators/python.py", line 192, in execute
    return_value = self.execute_callable()
  File "/home/airflow/.local/lib/python3.8/site-packages/airflow/operators/python.py", line 209, in execute_callable
    return self.python_callable(*self.op_args, **self.op_kwargs)
  File "/opt/airflow/dags/teste_api2.py", line 32, in save_to_mysql
    df.to_sql(MYSQL_TABLE_NAME, con=engine, if_exists='append', index=False)
NameError: name 'MYSQL_TABLE_NAME' is not defined
[2024-02-17T23:52:30.889+0000] {taskinstance.py:1400} INFO - Marking task as FAILED. dag_id=api_to_mysql_with_xcom, task_id=save_to_mysql, execution_date=20240217T235226, start_date=20240217T235230, end_date=20240217T235230
[2024-02-17T23:52:30.917+0000] {standard_task_runner.py:104} ERROR - Failed to execute job 27 for task save_to_mysql (name 'MYSQL_TABLE_NAME' is not defined; 22828)
[2024-02-17T23:52:30.961+0000] {local_task_job_runner.py:228} INFO - Task exited with return code 1
[2024-02-17T23:52:31.020+0000] {taskinstance.py:2778} INFO - 0 downstream tasks scheduled from follow-on schedule check
