[2024-02-17T18:48:42.647+0000] {taskinstance.py:1159} INFO - Dependencies all met for dep_context=non-requeueable deps ti=<TaskInstance: api_to_mysql.load_data_to_mysql manual__2024-02-17T18:48:36.858644+00:00 [queued]>
[2024-02-17T18:48:42.656+0000] {taskinstance.py:1159} INFO - Dependencies all met for dep_context=requeueable deps ti=<TaskInstance: api_to_mysql.load_data_to_mysql manual__2024-02-17T18:48:36.858644+00:00 [queued]>
[2024-02-17T18:48:42.656+0000] {taskinstance.py:1361} INFO - Starting attempt 1 of 1
[2024-02-17T18:48:42.671+0000] {taskinstance.py:1382} INFO - Executing <Task(PythonOperator): load_data_to_mysql> on 2024-02-17 18:48:36.858644+00:00
[2024-02-17T18:48:42.677+0000] {standard_task_runner.py:57} INFO - Started process 18107 to run task
[2024-02-17T18:48:42.679+0000] {standard_task_runner.py:84} INFO - Running: ['airflow', 'tasks', 'run', 'api_to_mysql', 'load_data_to_mysql', 'manual__2024-02-17T18:48:36.858644+00:00', '--job-id', '13', '--raw', '--subdir', 'DAGS_FOLDER/teste_api_to_mysql.py', '--cfg-path', '/tmp/tmp0ndzdae2']
[2024-02-17T18:48:42.680+0000] {standard_task_runner.py:85} INFO - Job 13: Subtask load_data_to_mysql
[2024-02-17T18:48:42.823+0000] {task_command.py:416} INFO - Running <TaskInstance: api_to_mysql.load_data_to_mysql manual__2024-02-17T18:48:36.858644+00:00 [running]> on host airflow-worker
[2024-02-17T18:48:43.064+0000] {taskinstance.py:1662} INFO - Exporting env vars: AIRFLOW_CTX_DAG_OWNER='airflow' AIRFLOW_CTX_DAG_ID='api_to_mysql' AIRFLOW_CTX_TASK_ID='load_data_to_mysql' AIRFLOW_CTX_EXECUTION_DATE='2024-02-17T18:48:36.858644+00:00' AIRFLOW_CTX_TRY_NUMBER='1' AIRFLOW_CTX_DAG_RUN_ID='manual__2024-02-17T18:48:36.858644+00:00'
[2024-02-17T18:48:43.066+0000] {taskinstance.py:1937} ERROR - Task failed with exception
Traceback (most recent call last):
  File "/home/airflow/.local/lib/python3.8/site-packages/airflow/operators/python.py", line 189, in execute
    context_merge(context, self.op_kwargs, templates_dict=self.templates_dict)
  File "/home/airflow/.local/lib/python3.8/site-packages/airflow/utils/context.py", line 260, in context_merge
    context.update(*args, **kwargs)
  File "/usr/local/lib/python3.8/_collections_abc.py", line 837, in update
    for key, value in other:
ValueError: too many values to unpack (expected 2)
[2024-02-17T18:48:43.106+0000] {taskinstance.py:1400} INFO - Marking task as FAILED. dag_id=api_to_mysql, task_id=load_data_to_mysql, execution_date=20240217T184836, start_date=20240217T184842, end_date=20240217T184843
[2024-02-17T18:48:43.135+0000] {standard_task_runner.py:104} ERROR - Failed to execute job 13 for task load_data_to_mysql (too many values to unpack (expected 2); 18107)
[2024-02-17T18:48:43.146+0000] {local_task_job_runner.py:228} INFO - Task exited with return code 1
[2024-02-17T18:48:43.201+0000] {taskinstance.py:2778} INFO - 0 downstream tasks scheduled from follow-on schedule check
