[2024-02-17T18:30:11.338+0000] {taskinstance.py:1159} INFO - Dependencies all met for dep_context=non-requeueable deps ti=<TaskInstance: api_to_mysql.load_data_to_mysql manual__2024-02-17T18:30:04.466996+00:00 [queued]>
[2024-02-17T18:30:11.347+0000] {taskinstance.py:1159} INFO - Dependencies all met for dep_context=requeueable deps ti=<TaskInstance: api_to_mysql.load_data_to_mysql manual__2024-02-17T18:30:04.466996+00:00 [queued]>
[2024-02-17T18:30:11.347+0000] {taskinstance.py:1361} INFO - Starting attempt 1 of 1
[2024-02-17T18:30:11.362+0000] {taskinstance.py:1382} INFO - Executing <Task(PythonOperator): load_data_to_mysql> on 2024-02-17 18:30:04.466996+00:00
[2024-02-17T18:30:11.368+0000] {standard_task_runner.py:57} INFO - Started process 17813 to run task
[2024-02-17T18:30:11.370+0000] {standard_task_runner.py:84} INFO - Running: ['airflow', 'tasks', 'run', 'api_to_mysql', 'load_data_to_mysql', 'manual__2024-02-17T18:30:04.466996+00:00', '--job-id', '11', '--raw', '--subdir', 'DAGS_FOLDER/teste_api_to_mysql.py', '--cfg-path', '/tmp/tmpvq_gmaab']
[2024-02-17T18:30:11.371+0000] {standard_task_runner.py:85} INFO - Job 11: Subtask load_data_to_mysql
[2024-02-17T18:30:11.523+0000] {task_command.py:416} INFO - Running <TaskInstance: api_to_mysql.load_data_to_mysql manual__2024-02-17T18:30:04.466996+00:00 [running]> on host airflow-worker
[2024-02-17T18:30:11.766+0000] {taskinstance.py:1662} INFO - Exporting env vars: AIRFLOW_CTX_DAG_OWNER='airflow' AIRFLOW_CTX_DAG_ID='api_to_mysql' AIRFLOW_CTX_TASK_ID='load_data_to_mysql' AIRFLOW_CTX_EXECUTION_DATE='2024-02-17T18:30:04.466996+00:00' AIRFLOW_CTX_TRY_NUMBER='1' AIRFLOW_CTX_DAG_RUN_ID='manual__2024-02-17T18:30:04.466996+00:00'
[2024-02-17T18:30:11.768+0000] {taskinstance.py:1937} ERROR - Task failed with exception
Traceback (most recent call last):
  File "/home/airflow/.local/lib/python3.8/site-packages/airflow/operators/python.py", line 192, in execute
    return_value = self.execute_callable()
  File "/home/airflow/.local/lib/python3.8/site-packages/airflow/operators/python.py", line 209, in execute_callable
    return self.python_callable(*self.op_args, **self.op_kwargs)
TypeError: load_data_to_mysql() missing 1 required positional argument: 'data'
[2024-02-17T18:30:11.804+0000] {taskinstance.py:1400} INFO - Marking task as FAILED. dag_id=api_to_mysql, task_id=load_data_to_mysql, execution_date=20240217T183004, start_date=20240217T183011, end_date=20240217T183011
[2024-02-17T18:30:11.843+0000] {standard_task_runner.py:104} ERROR - Failed to execute job 11 for task load_data_to_mysql (load_data_to_mysql() missing 1 required positional argument: 'data'; 17813)
[2024-02-17T18:30:11.867+0000] {local_task_job_runner.py:228} INFO - Task exited with return code 1
[2024-02-17T18:30:11.924+0000] {taskinstance.py:2778} INFO - 0 downstream tasks scheduled from follow-on schedule check
